[2024-01-05T07:34:45.513+0000] {taskinstance.py:1957} INFO - Dependencies all met for dep_context=non-requeueable deps ti=<TaskInstance: mysql_to_postgres.transfer_payment_data scheduled__2024-01-04T08:30:00+00:00 [queued]>
[2024-01-05T07:34:45.515+0000] {taskinstance.py:1957} INFO - Dependencies all met for dep_context=requeueable deps ti=<TaskInstance: mysql_to_postgres.transfer_payment_data scheduled__2024-01-04T08:30:00+00:00 [queued]>
[2024-01-05T07:34:45.515+0000] {taskinstance.py:2171} INFO - Starting attempt 1 of 2
[2024-01-05T07:34:45.521+0000] {taskinstance.py:2192} INFO - Executing <Task(PythonOperator): transfer_payment_data> on 2024-01-04 08:30:00+00:00
[2024-01-05T07:34:45.523+0000] {standard_task_runner.py:60} INFO - Started process 195 to run task
[2024-01-05T07:34:45.525+0000] {standard_task_runner.py:87} INFO - Running: ['airflow', 'tasks', 'run', 'mysql_to_postgres', 'transfer_payment_data', 'scheduled__2024-01-04T08:30:00+00:00', '--job-id', '14', '--raw', '--subdir', 'DAGS_FOLDER/mysql_to_postgres.py', '--cfg-path', '/tmp/tmpirqz1l6c']
[2024-01-05T07:34:45.526+0000] {standard_task_runner.py:88} INFO - Job 14: Subtask transfer_payment_data
[2024-01-05T07:34:45.543+0000] {task_command.py:423} INFO - Running <TaskInstance: mysql_to_postgres.transfer_payment_data scheduled__2024-01-04T08:30:00+00:00 [running]> on host 0b5bad337f42
[2024-01-05T07:34:45.632+0000] {taskinstance.py:2481} INFO - Exporting env vars: AIRFLOW_CTX_DAG_OWNER='airflow' AIRFLOW_CTX_DAG_ID='mysql_to_postgres' AIRFLOW_CTX_TASK_ID='transfer_payment_data' AIRFLOW_CTX_EXECUTION_DATE='2024-01-04T08:30:00+00:00' AIRFLOW_CTX_TRY_NUMBER='1' AIRFLOW_CTX_DAG_RUN_ID='scheduled__2024-01-04T08:30:00+00:00'
[2024-01-05T07:34:45.635+0000] {taskinstance.py:2699} ERROR - Task failed with exception
Traceback (most recent call last):
  File "/home/airflow/.local/lib/python3.8/site-packages/airflow/models/taskinstance.py", line 433, in _execute_task
    result = execute_callable(context=context, **execute_callable_kwargs)
  File "/home/airflow/.local/lib/python3.8/site-packages/airflow/operators/python.py", line 199, in execute
    return_value = self.execute_callable()
  File "/home/airflow/.local/lib/python3.8/site-packages/airflow/operators/python.py", line 216, in execute_callable
    return self.python_callable(*self.op_args, **self.op_kwargs)
  File "/opt/airflow/dags/mysql_to_postgres.py", line 17, in transfer_data
    mysql_conn = mysql_hook.get_conn()
  File "/home/airflow/.local/lib/python3.8/site-packages/airflow/providers/mysql/hooks/mysql.py", line 187, in get_conn
    conn = self.connection or self.get_connection(getattr(self, self.conn_name_attr))
  File "/home/airflow/.local/lib/python3.8/site-packages/airflow/hooks/base.py", line 82, in get_connection
    conn = Connection.get_connection_from_secrets(conn_id)
  File "/home/airflow/.local/lib/python3.8/site-packages/airflow/models/connection.py", line 479, in get_connection_from_secrets
    raise AirflowNotFoundException(f"The conn_id `{conn_id}` isn't defined")
airflow.exceptions.AirflowNotFoundException: The conn_id `mysql_default` isn't defined
[2024-01-05T07:34:45.637+0000] {taskinstance.py:1138} INFO - Marking task as UP_FOR_RETRY. dag_id=mysql_to_postgres, task_id=transfer_payment_data, execution_date=20240104T083000, start_date=20240105T073445, end_date=20240105T073445
[2024-01-05T07:34:45.640+0000] {standard_task_runner.py:107} ERROR - Failed to execute job 14 for task transfer_payment_data (The conn_id `mysql_default` isn't defined; 195)
[2024-01-05T07:34:45.673+0000] {local_task_job_runner.py:234} INFO - Task exited with return code 1
[2024-01-05T07:34:45.679+0000] {taskinstance.py:3281} INFO - 0 downstream tasks scheduled from follow-on schedule check
