[2024-01-05T08:09:00.182+0000] {taskinstance.py:1957} INFO - Dependencies all met for dep_context=non-requeueable deps ti=<TaskInstance: mysql_to_postgres.transfer_payment_data manual__2024-01-05T08:08:57.967856+00:00 [queued]>
[2024-01-05T08:09:00.185+0000] {taskinstance.py:1957} INFO - Dependencies all met for dep_context=requeueable deps ti=<TaskInstance: mysql_to_postgres.transfer_payment_data manual__2024-01-05T08:08:57.967856+00:00 [queued]>
[2024-01-05T08:09:00.185+0000] {taskinstance.py:2171} INFO - Starting attempt 1 of 2
[2024-01-05T08:09:00.190+0000] {taskinstance.py:2192} INFO - Executing <Task(PythonOperator): transfer_payment_data> on 2024-01-05 08:08:57.967856+00:00
[2024-01-05T08:09:00.194+0000] {standard_task_runner.py:60} INFO - Started process 96 to run task
[2024-01-05T08:09:00.199+0000] {standard_task_runner.py:87} INFO - Running: ['airflow', 'tasks', 'run', 'mysql_to_postgres', 'transfer_payment_data', 'manual__2024-01-05T08:08:57.967856+00:00', '--job-id', '2', '--raw', '--subdir', 'DAGS_FOLDER/mysql_to_postgres.py', '--cfg-path', '/tmp/tmp_a9v4o4f']
[2024-01-05T08:09:00.201+0000] {standard_task_runner.py:88} INFO - Job 2: Subtask transfer_payment_data
[2024-01-05T08:09:00.227+0000] {task_command.py:423} INFO - Running <TaskInstance: mysql_to_postgres.transfer_payment_data manual__2024-01-05T08:08:57.967856+00:00 [running]> on host 47dc055b3fc2
[2024-01-05T08:09:00.366+0000] {taskinstance.py:2481} INFO - Exporting env vars: AIRFLOW_CTX_DAG_OWNER='airflow' AIRFLOW_CTX_DAG_ID='mysql_to_postgres' AIRFLOW_CTX_TASK_ID='transfer_payment_data' AIRFLOW_CTX_EXECUTION_DATE='2024-01-05T08:08:57.967856+00:00' AIRFLOW_CTX_TRY_NUMBER='1' AIRFLOW_CTX_DAG_RUN_ID='manual__2024-01-05T08:08:57.967856+00:00'
[2024-01-05T08:09:00.369+0000] {taskinstance.py:2699} ERROR - Task failed with exception
Traceback (most recent call last):
  File "/home/airflow/.local/lib/python3.8/site-packages/airflow/models/taskinstance.py", line 433, in _execute_task
    result = execute_callable(context=context, **execute_callable_kwargs)
  File "/home/airflow/.local/lib/python3.8/site-packages/airflow/operators/python.py", line 199, in execute
    return_value = self.execute_callable()
  File "/home/airflow/.local/lib/python3.8/site-packages/airflow/operators/python.py", line 216, in execute_callable
    return self.python_callable(*self.op_args, **self.op_kwargs)
  File "/opt/airflow/dags/mysql_to_postgres.py", line 17, in transfer_data
    mysql_conn = mysql_hook.get_conn()
  File "/home/airflow/.local/lib/python3.8/site-packages/airflow/providers/mysql/hooks/mysql.py", line 187, in get_conn
    conn = self.connection or self.get_connection(getattr(self, self.conn_name_attr))
  File "/home/airflow/.local/lib/python3.8/site-packages/airflow/hooks/base.py", line 82, in get_connection
    conn = Connection.get_connection_from_secrets(conn_id)
  File "/home/airflow/.local/lib/python3.8/site-packages/airflow/models/connection.py", line 479, in get_connection_from_secrets
    raise AirflowNotFoundException(f"The conn_id `{conn_id}` isn't defined")
airflow.exceptions.AirflowNotFoundException: The conn_id `mysql_default` isn't defined
[2024-01-05T08:09:00.372+0000] {taskinstance.py:1138} INFO - Marking task as UP_FOR_RETRY. dag_id=mysql_to_postgres, task_id=transfer_payment_data, execution_date=20240105T080857, start_date=20240105T080900, end_date=20240105T080900
[2024-01-05T08:09:00.376+0000] {standard_task_runner.py:107} ERROR - Failed to execute job 2 for task transfer_payment_data (The conn_id `mysql_default` isn't defined; 96)
[2024-01-05T08:09:00.388+0000] {local_task_job_runner.py:234} INFO - Task exited with return code 1
[2024-01-05T08:09:00.394+0000] {taskinstance.py:3281} INFO - 0 downstream tasks scheduled from follow-on schedule check
