[2024-01-05T07:32:18.824+0000] {taskinstance.py:1957} INFO - Dependencies all met for dep_context=non-requeueable deps ti=<TaskInstance: mysql_to_postgres.transfer_payment_data scheduled__2024-01-04T07:35:00+00:00 [queued]>
[2024-01-05T07:32:18.826+0000] {taskinstance.py:1957} INFO - Dependencies all met for dep_context=requeueable deps ti=<TaskInstance: mysql_to_postgres.transfer_payment_data scheduled__2024-01-04T07:35:00+00:00 [queued]>
[2024-01-05T07:32:18.826+0000] {taskinstance.py:2171} INFO - Starting attempt 1 of 2
[2024-01-05T07:32:18.832+0000] {taskinstance.py:2192} INFO - Executing <Task(PythonOperator): transfer_payment_data> on 2024-01-04 07:35:00+00:00
[2024-01-05T07:32:18.836+0000] {standard_task_runner.py:60} INFO - Started process 102 to run task
[2024-01-05T07:32:18.839+0000] {standard_task_runner.py:87} INFO - Running: ['airflow', 'tasks', 'run', 'mysql_to_postgres', 'transfer_payment_data', 'scheduled__2024-01-04T07:35:00+00:00', '--job-id', '4', '--raw', '--subdir', 'DAGS_FOLDER/mysql_to_postgres.py', '--cfg-path', '/tmp/tmpdwmhxn5o']
[2024-01-05T07:32:18.841+0000] {standard_task_runner.py:88} INFO - Job 4: Subtask transfer_payment_data
[2024-01-05T07:32:18.861+0000] {task_command.py:423} INFO - Running <TaskInstance: mysql_to_postgres.transfer_payment_data scheduled__2024-01-04T07:35:00+00:00 [running]> on host 3322ac3f9396
[2024-01-05T07:32:18.975+0000] {taskinstance.py:2481} INFO - Exporting env vars: AIRFLOW_CTX_DAG_OWNER='airflow' AIRFLOW_CTX_DAG_ID='mysql_to_postgres' AIRFLOW_CTX_TASK_ID='transfer_payment_data' AIRFLOW_CTX_EXECUTION_DATE='2024-01-04T07:35:00+00:00' AIRFLOW_CTX_TRY_NUMBER='1' AIRFLOW_CTX_DAG_RUN_ID='scheduled__2024-01-04T07:35:00+00:00'
[2024-01-05T07:32:18.979+0000] {taskinstance.py:2699} ERROR - Task failed with exception
Traceback (most recent call last):
  File "/home/airflow/.local/lib/python3.8/site-packages/airflow/models/taskinstance.py", line 433, in _execute_task
    result = execute_callable(context=context, **execute_callable_kwargs)
  File "/home/airflow/.local/lib/python3.8/site-packages/airflow/operators/python.py", line 199, in execute
    return_value = self.execute_callable()
  File "/home/airflow/.local/lib/python3.8/site-packages/airflow/operators/python.py", line 216, in execute_callable
    return self.python_callable(*self.op_args, **self.op_kwargs)
  File "/opt/airflow/dags/mysql_to_postgres.py", line 17, in transfer_data
    mysql_conn = mysql_hook.get_conn()
  File "/home/airflow/.local/lib/python3.8/site-packages/airflow/providers/mysql/hooks/mysql.py", line 187, in get_conn
    conn = self.connection or self.get_connection(getattr(self, self.conn_name_attr))
  File "/home/airflow/.local/lib/python3.8/site-packages/airflow/hooks/base.py", line 82, in get_connection
    conn = Connection.get_connection_from_secrets(conn_id)
  File "/home/airflow/.local/lib/python3.8/site-packages/airflow/models/connection.py", line 479, in get_connection_from_secrets
    raise AirflowNotFoundException(f"The conn_id `{conn_id}` isn't defined")
airflow.exceptions.AirflowNotFoundException: The conn_id `mysql_default` isn't defined
[2024-01-05T07:32:18.981+0000] {taskinstance.py:1138} INFO - Marking task as UP_FOR_RETRY. dag_id=mysql_to_postgres, task_id=transfer_payment_data, execution_date=20240104T073500, start_date=20240105T073218, end_date=20240105T073218
[2024-01-05T07:32:18.987+0000] {standard_task_runner.py:107} ERROR - Failed to execute job 4 for task transfer_payment_data (The conn_id `mysql_default` isn't defined; 102)
[2024-01-05T07:32:19.029+0000] {local_task_job_runner.py:234} INFO - Task exited with return code 1
[2024-01-05T07:32:19.053+0000] {taskinstance.py:3281} INFO - 0 downstream tasks scheduled from follow-on schedule check
[2024-01-05T07:34:25.675+0000] {taskinstance.py:1957} INFO - Dependencies all met for dep_context=non-requeueable deps ti=<TaskInstance: mysql_to_postgres.transfer_payment_data scheduled__2024-01-04T07:35:00+00:00 [queued]>
[2024-01-05T07:34:25.678+0000] {taskinstance.py:1957} INFO - Dependencies all met for dep_context=requeueable deps ti=<TaskInstance: mysql_to_postgres.transfer_payment_data scheduled__2024-01-04T07:35:00+00:00 [queued]>
[2024-01-05T07:34:25.678+0000] {taskinstance.py:2171} INFO - Starting attempt 1 of 2
[2024-01-05T07:34:25.684+0000] {taskinstance.py:2192} INFO - Executing <Task(PythonOperator): transfer_payment_data> on 2024-01-04 07:35:00+00:00
[2024-01-05T07:34:25.688+0000] {standard_task_runner.py:60} INFO - Started process 74 to run task
[2024-01-05T07:34:25.692+0000] {standard_task_runner.py:87} INFO - Running: ['airflow', 'tasks', 'run', 'mysql_to_postgres', 'transfer_payment_data', 'scheduled__2024-01-04T07:35:00+00:00', '--job-id', '2', '--raw', '--subdir', 'DAGS_FOLDER/mysql_to_postgres.py', '--cfg-path', '/tmp/tmp89md1cth']
[2024-01-05T07:34:25.694+0000] {standard_task_runner.py:88} INFO - Job 2: Subtask transfer_payment_data
[2024-01-05T07:34:25.744+0000] {task_command.py:423} INFO - Running <TaskInstance: mysql_to_postgres.transfer_payment_data scheduled__2024-01-04T07:35:00+00:00 [running]> on host 0b5bad337f42
[2024-01-05T07:34:25.942+0000] {taskinstance.py:2481} INFO - Exporting env vars: AIRFLOW_CTX_DAG_OWNER='airflow' AIRFLOW_CTX_DAG_ID='mysql_to_postgres' AIRFLOW_CTX_TASK_ID='transfer_payment_data' AIRFLOW_CTX_EXECUTION_DATE='2024-01-04T07:35:00+00:00' AIRFLOW_CTX_TRY_NUMBER='1' AIRFLOW_CTX_DAG_RUN_ID='scheduled__2024-01-04T07:35:00+00:00'
[2024-01-05T07:34:25.947+0000] {taskinstance.py:2699} ERROR - Task failed with exception
Traceback (most recent call last):
  File "/home/airflow/.local/lib/python3.8/site-packages/airflow/models/taskinstance.py", line 433, in _execute_task
    result = execute_callable(context=context, **execute_callable_kwargs)
  File "/home/airflow/.local/lib/python3.8/site-packages/airflow/operators/python.py", line 199, in execute
    return_value = self.execute_callable()
  File "/home/airflow/.local/lib/python3.8/site-packages/airflow/operators/python.py", line 216, in execute_callable
    return self.python_callable(*self.op_args, **self.op_kwargs)
  File "/opt/airflow/dags/mysql_to_postgres.py", line 17, in transfer_data
    mysql_conn = mysql_hook.get_conn()
  File "/home/airflow/.local/lib/python3.8/site-packages/airflow/providers/mysql/hooks/mysql.py", line 187, in get_conn
    conn = self.connection or self.get_connection(getattr(self, self.conn_name_attr))
  File "/home/airflow/.local/lib/python3.8/site-packages/airflow/hooks/base.py", line 82, in get_connection
    conn = Connection.get_connection_from_secrets(conn_id)
  File "/home/airflow/.local/lib/python3.8/site-packages/airflow/models/connection.py", line 479, in get_connection_from_secrets
    raise AirflowNotFoundException(f"The conn_id `{conn_id}` isn't defined")
airflow.exceptions.AirflowNotFoundException: The conn_id `mysql_default` isn't defined
[2024-01-05T07:34:25.952+0000] {taskinstance.py:1138} INFO - Marking task as UP_FOR_RETRY. dag_id=mysql_to_postgres, task_id=transfer_payment_data, execution_date=20240104T073500, start_date=20240105T073425, end_date=20240105T073425
[2024-01-05T07:34:25.957+0000] {standard_task_runner.py:107} ERROR - Failed to execute job 2 for task transfer_payment_data (The conn_id `mysql_default` isn't defined; 74)
[2024-01-05T07:34:25.997+0000] {local_task_job_runner.py:234} INFO - Task exited with return code 1
[2024-01-05T07:34:26.003+0000] {taskinstance.py:3281} INFO - 0 downstream tasks scheduled from follow-on schedule check
