[2024-01-05T09:43:00.833+0000] {taskinstance.py:1957} INFO - Dependencies all met for dep_context=non-requeueable deps ti=<TaskInstance: mysql_to_postgres.transfer_customer_data manual__2024-01-05T09:42:58.996759+00:00 [queued]>
[2024-01-05T09:43:00.838+0000] {taskinstance.py:1957} INFO - Dependencies all met for dep_context=requeueable deps ti=<TaskInstance: mysql_to_postgres.transfer_customer_data manual__2024-01-05T09:42:58.996759+00:00 [queued]>
[2024-01-05T09:43:00.838+0000] {taskinstance.py:2171} INFO - Starting attempt 1 of 4
[2024-01-05T09:43:00.847+0000] {taskinstance.py:2192} INFO - Executing <Task(PythonOperator): transfer_customer_data> on 2024-01-05 09:42:58.996759+00:00
[2024-01-05T09:43:00.853+0000] {standard_task_runner.py:60} INFO - Started process 333 to run task
[2024-01-05T09:43:00.856+0000] {standard_task_runner.py:87} INFO - Running: ['airflow', 'tasks', 'run', 'mysql_to_postgres', 'transfer_customer_data', 'manual__2024-01-05T09:42:58.996759+00:00', '--job-id', '2', '--raw', '--subdir', 'DAGS_FOLDER/mysql_to_postgres.py', '--cfg-path', '/tmp/tmp9vjyt4xl']
[2024-01-05T09:43:00.859+0000] {standard_task_runner.py:88} INFO - Job 2: Subtask transfer_customer_data
[2024-01-05T09:43:00.873+0000] {logging_mixin.py:188} WARNING - /home/airflow/.local/lib/python3.8/site-packages/airflow/settings.py:195 DeprecationWarning: The sql_alchemy_conn option in [core] has been moved to the sql_alchemy_conn option in [database] - the old setting has been used, but please update your config.
[2024-01-05T09:43:00.897+0000] {task_command.py:423} INFO - Running <TaskInstance: mysql_to_postgres.transfer_customer_data manual__2024-01-05T09:42:58.996759+00:00 [running]> on host 23cbfe1add96
[2024-01-05T09:43:00.952+0000] {taskinstance.py:2481} INFO - Exporting env vars: AIRFLOW_CTX_DAG_OWNER='airflow' AIRFLOW_CTX_DAG_ID='mysql_to_postgres' AIRFLOW_CTX_TASK_ID='transfer_customer_data' AIRFLOW_CTX_EXECUTION_DATE='2024-01-05T09:42:58.996759+00:00' AIRFLOW_CTX_TRY_NUMBER='1' AIRFLOW_CTX_DAG_RUN_ID='manual__2024-01-05T09:42:58.996759+00:00'
[2024-01-05T09:43:01.153+0000] {logging_mixin.py:188} INFO - Error: relation "sakila.customer" does not exist
LINE 1: SELECT * FROM sakila.customer
                      ^
[2024-01-05T09:43:01.154+0000] {taskinstance.py:2699} ERROR - Task failed with exception
Traceback (most recent call last):
  File "/opt/airflow/dags/mysql_to_postgres.py", line 43, in transfer_data
    postgres_cursor.execute("SELECT * FROM sakila.customer")
psycopg2.errors.UndefinedTable: relation "sakila.customer" does not exist
LINE 1: SELECT * FROM sakila.customer
                      ^


During handling of the above exception, another exception occurred:

Traceback (most recent call last):
  File "/home/airflow/.local/lib/python3.8/site-packages/airflow/models/taskinstance.py", line 433, in _execute_task
    result = execute_callable(context=context, **execute_callable_kwargs)
  File "/home/airflow/.local/lib/python3.8/site-packages/airflow/operators/python.py", line 199, in execute
    return_value = self.execute_callable()
  File "/home/airflow/.local/lib/python3.8/site-packages/airflow/operators/python.py", line 216, in execute_callable
    return self.python_callable(*self.op_args, **self.op_kwargs)
  File "/opt/airflow/dags/mysql_to_postgres.py", line 51, in transfer_data
    raise AirflowFailException(f"Failed to transfer data: {str(e)}")
airflow.exceptions.AirflowFailException: Failed to transfer data: relation "sakila.customer" does not exist
LINE 1: SELECT * FROM sakila.customer
                      ^

[2024-01-05T09:43:01.169+0000] {taskinstance.py:1138} INFO - Immediate failure requested. Marking task as FAILED. dag_id=mysql_to_postgres, task_id=transfer_customer_data, execution_date=20240105T094258, start_date=20240105T094300, end_date=20240105T094301
[2024-01-05T09:43:01.177+0000] {standard_task_runner.py:107} ERROR - Failed to execute job 2 for task transfer_customer_data (Failed to transfer data: relation "sakila.customer" does not exist
LINE 1: SELECT * FROM sakila.customer
                      ^
; 333)
[2024-01-05T09:43:01.195+0000] {local_task_job_runner.py:234} INFO - Task exited with return code 1
[2024-01-05T09:43:01.209+0000] {taskinstance.py:3281} INFO - 0 downstream tasks scheduled from follow-on schedule check
