[2024-01-05T09:06:20.657+0000] {taskinstance.py:1957} INFO - Dependencies all met for dep_context=non-requeueable deps ti=<TaskInstance: mysql_to_postgres.transfer_payment_data manual__2024-01-05T09:06:18.305083+00:00 [queued]>
[2024-01-05T09:06:20.662+0000] {taskinstance.py:1957} INFO - Dependencies all met for dep_context=requeueable deps ti=<TaskInstance: mysql_to_postgres.transfer_payment_data manual__2024-01-05T09:06:18.305083+00:00 [queued]>
[2024-01-05T09:06:20.662+0000] {taskinstance.py:2171} INFO - Starting attempt 1 of 4
[2024-01-05T09:06:20.669+0000] {taskinstance.py:2192} INFO - Executing <Task(PythonOperator): transfer_payment_data> on 2024-01-05 09:06:18.305083+00:00
[2024-01-05T09:06:20.672+0000] {standard_task_runner.py:60} INFO - Started process 206 to run task
[2024-01-05T09:06:20.679+0000] {standard_task_runner.py:87} INFO - Running: ['airflow', 'tasks', 'run', 'mysql_to_postgres', 'transfer_payment_data', 'manual__2024-01-05T09:06:18.305083+00:00', '--job-id', '3', '--raw', '--subdir', 'DAGS_FOLDER/mysql_to_postgres.py', '--cfg-path', '/tmp/tmpr2gomgg9']
[2024-01-05T09:06:20.685+0000] {standard_task_runner.py:88} INFO - Job 3: Subtask transfer_payment_data
[2024-01-05T09:06:20.707+0000] {logging_mixin.py:188} WARNING - /home/airflow/.local/lib/python3.8/site-packages/airflow/settings.py:195 DeprecationWarning: The sql_alchemy_conn option in [core] has been moved to the sql_alchemy_conn option in [database] - the old setting has been used, but please update your config.
[2024-01-05T09:06:20.746+0000] {task_command.py:423} INFO - Running <TaskInstance: mysql_to_postgres.transfer_payment_data manual__2024-01-05T09:06:18.305083+00:00 [running]> on host 854ca78f82a1
[2024-01-05T09:06:20.970+0000] {taskinstance.py:2481} INFO - Exporting env vars: AIRFLOW_CTX_DAG_OWNER='airflow' AIRFLOW_CTX_DAG_ID='mysql_to_postgres' AIRFLOW_CTX_TASK_ID='transfer_payment_data' AIRFLOW_CTX_EXECUTION_DATE='2024-01-05T09:06:18.305083+00:00' AIRFLOW_CTX_TRY_NUMBER='1' AIRFLOW_CTX_DAG_RUN_ID='manual__2024-01-05T09:06:18.305083+00:00'
[2024-01-05T09:06:20.976+0000] {base.py:83} INFO - Using connection ID 'mysql_default' for task execution.
[2024-01-05T09:06:20.993+0000] {logging_mixin.py:188} INFO - Error: The conn_id `postgres_default` isn't defined
[2024-01-05T09:06:20.993+0000] {taskinstance.py:2699} ERROR - Task failed with exception
Traceback (most recent call last):
  File "/opt/airflow/dags/mysql_to_postgres.py", line 28, in transfer_data
    postgres_conn = postgres_hook.get_conn()
  File "/home/airflow/.local/lib/python3.8/site-packages/airflow/providers/postgres/hooks/postgres.py", line 128, in get_conn
    conn = deepcopy(self.connection or self.get_connection(conn_id))
  File "/home/airflow/.local/lib/python3.8/site-packages/airflow/hooks/base.py", line 82, in get_connection
    conn = Connection.get_connection_from_secrets(conn_id)
  File "/home/airflow/.local/lib/python3.8/site-packages/airflow/models/connection.py", line 479, in get_connection_from_secrets
    raise AirflowNotFoundException(f"The conn_id `{conn_id}` isn't defined")
airflow.exceptions.AirflowNotFoundException: The conn_id `postgres_default` isn't defined

During handling of the above exception, another exception occurred:

Traceback (most recent call last):
  File "/home/airflow/.local/lib/python3.8/site-packages/airflow/models/taskinstance.py", line 433, in _execute_task
    result = execute_callable(context=context, **execute_callable_kwargs)
  File "/home/airflow/.local/lib/python3.8/site-packages/airflow/operators/python.py", line 199, in execute
    return_value = self.execute_callable()
  File "/home/airflow/.local/lib/python3.8/site-packages/airflow/operators/python.py", line 216, in execute_callable
    return self.python_callable(*self.op_args, **self.op_kwargs)
  File "/opt/airflow/dags/mysql_to_postgres.py", line 40, in transfer_data
    raise AirflowFailException(f"Failed to transfer data: {str(e)}")
airflow.exceptions.AirflowFailException: Failed to transfer data: The conn_id `postgres_default` isn't defined
[2024-01-05T09:06:21.000+0000] {taskinstance.py:1138} INFO - Immediate failure requested. Marking task as FAILED. dag_id=mysql_to_postgres, task_id=transfer_payment_data, execution_date=20240105T090618, start_date=20240105T090620, end_date=20240105T090621
[2024-01-05T09:06:21.006+0000] {standard_task_runner.py:107} ERROR - Failed to execute job 3 for task transfer_payment_data (Failed to transfer data: The conn_id `postgres_default` isn't defined; 206)
[2024-01-05T09:06:21.021+0000] {local_task_job_runner.py:234} INFO - Task exited with return code 1
[2024-01-05T09:06:21.033+0000] {taskinstance.py:3281} INFO - 0 downstream tasks scheduled from follow-on schedule check
